<?xml version="1.0" encoding="utf-8"?>
<robot name="urdf_moveit" xmlns:xacro="http://www.ros.org/wiki/xacro">

  <link name="world"/>
  
  <joint name="world_to_base" type="fixed">
    <parent link="world"/>
    <child link="base_link"/>
  </joint>

   <link
    name="base_link">
    <inertial>
      <origin
        xyz="0.052962 -0.094417 0.049594"
        rpy="0 0 0" />
      <mass
        value="0.119" />
      <inertia
        ixx="0.00013383"
        ixy="6.8295E-11"
        ixz="3.6366E-06"
        iyy="0.00014723"
        iyz="5.1205E-12"
        izz="0.000214" />
    </inertial>
    <visual>
      <origin
        xyz="0 0 0"
        rpy="0 0 0" />
      <geometry>
        <mesh
          filename="file:///home/ahmed/Robotics-Project-main/src/my_robot_arm_pkg/meshes/base_link.STL" />
      </geometry>
      <material
        name="">
        <color
          rgba="0.2 0.2 0.2 1.0" />
      </material>
    </visual>
    <collision>
      <origin
        xyz="0 0 0"
        rpy="0 0 0" />
      <geometry>
        <mesh
          filename="file:///home/ahmed/Robotics-Project-main/src/my_robot_arm_pkg/meshes/base_link.STL" />
      </geometry>
    </collision>
  </link>
  <link
    name="link1">
    <inertial>
      <origin
        xyz="0.0059207 -0.012971 0.022635"
        rpy="0 0 0" />
      <mass
        value="0.093" />
      <inertia
        ixx="5.7426E-05"
        ixy="-5.6415E-06"
        ixz="3.3676E-06"
        iyy="5.9444E-05"
        iyz="8.899E-06"
        izz="6.238E-05" />
    </inertial>
    <visual>
      <origin
        xyz="0 0 0"
        rpy="0 0 0" />
      <geometry>
        <mesh
          filename="file:///home/ahmed/Robotics-Project-main/src/my_robot_arm_pkg/meshes/link1.STL" />
      </geometry>
      <material
        name="">
        <color
          rgba="0.52 0.58 0.65 1.0" />
      </material>
    </visual>
    <collision>
      <origin
        xyz="0 0 0"
        rpy="0 0 0" />
      <geometry>
        <mesh
          filename="file:///home/ahmed/Robotics-Project-main/src/my_robot_arm_pkg/meshes/link1.STL" />
      </geometry>
    </collision>
  </link>
  <joint
    name="J1"
    type="revolute">
    <origin
      xyz="0.05542 -0.094417 0.082"
      rpy="0 0 0" />
    <parent
      link="base_link" />
    <child
      link="link1" />
    <axis
      xyz="0 0 1" />
    <limit
      lower="0"
      upper="3.14"
      effort="0.92"
      velocity="6.16" />
  </joint>
  <link
    name="link2">
    <inertial>
      <origin
        xyz="-0.00012999 0.058589 0.0077691"
        rpy="0 0 0" />
      <mass
        value="0.032" />
      <inertia
        ixx="0.00010704"
        ixy="-1.7383E-09"
        ixz="2.5177E-10"
        iyy="9.11E-06"
        iyz="2.396E-07"
        izz="0.00011184" />
    </inertial>
    <visual>
      <origin
        xyz="0 0 0"
        rpy="0 0 0" />
      <geometry>
        <mesh
          filename="file:///home/ahmed/Robotics-Project-main/src/my_robot_arm_pkg/meshes/link2.STL" />
      </geometry>
      <material
        name="">
        <color
          rgba="0.2 0.2 0.2 1.0" />
      </material>
    </visual>
    <collision>
      <origin
        xyz="0 0 0"
        rpy="0 0 0" />
      <geometry>
        <mesh
          filename="file:///home/ahmed/Robotics-Project-main/src/my_robot_arm_pkg/meshes/link2.STL" />
      </geometry>
    </collision>
  </link>
  <joint
    name="J2"
    type="revolute">
    <origin
      xyz="-0.0099117 -0.009936 0.040276"
      rpy="1.5708 0 -2.4836" />
    <parent
      link="link1" />
    <child
      link="link2" />
    <axis
      xyz="0 0 -1" />
    <limit
      lower="-1.57"
      upper="1.57"
      effort="0.92"
      velocity="6.16" />
  </joint>
  <link
    name="link3">
    <inertial>
      <origin
        xyz="0.045369 -4.58E-05 -0.01512"
        rpy="0 0 0" />
      <mass
        value="0.101" />
      <inertia
        ixx="1.8199E-05"
        ixy="-5.8051E-08"
        ixz="-4.9913E-08"
        iyy="6.8738E-05"
        iyz="4.0491E-09"
        izz="6.9563E-05" />
    </inertial>
    <visual>
      <origin
        xyz="0 0 0"
        rpy="0 0 0" />
      <geometry>
        <mesh
          filename="file:///home/ahmed/Robotics-Project-main/src/my_robot_arm_pkg/meshes/link3.STL" />
      </geometry>
      <material
        name="">
        <color
          rgba="0.2 0.2 0.2 1.0" />
      </material>
    </visual>
    <collision>
      <origin
        xyz="0 0 0"
        rpy="0 0 0" />
      <geometry>
        <mesh
          filename="file:///home/ahmed/Robotics-Project-main/src/my_robot_arm_pkg/meshes/link3.STL" />
      </geometry>
    </collision>
  </link>
  <joint
    name="J3"
    type="revolute">
    <origin
      xyz="0 0.12 0"
      rpy="0 0 0" />
    <parent
      link="link2" />
    <child
      link="link3" />
    <axis
      xyz="0 0 1" />
    <limit
      lower="-0.1"
      upper="3.14"
      effort="0.92"
      velocity="6.16" />
  </joint>
  <link
    name="link4">
    <inertial>
      <origin
        xyz="-0.0029037 0.043012 -0.0031096"
        rpy="0 0 0" />
      <mass
        value="0.0326" />
      <inertia
        ixx="1.9847E-05"
        ixy="2.5863E-06"
        ixz="-3.8847E-07"
        iyy="5.6319E-06"
        iyz="1.9904E-06"
        izz="1.8296E-05" />
    </inertial>
    <visual>
      <origin
        xyz="0 0 0"
        rpy="0 0 0" />
      <geometry>
        <mesh
          filename="file:///home/ahmed/Robotics-Project-main/src/my_robot_arm_pkg/meshes/link4.STL" />
      </geometry>
      <material
        name="">
        <color
          rgba="0.52 0.58 0.65 1.0" />
      </material>
    </visual>
    <collision>
      <origin
        xyz="0 0 0"
        rpy="0 0 0" />
      <geometry>
        <mesh
          filename="file:///home/ahmed/Robotics-Project-main/src/my_robot_arm_pkg/meshes/link4.STL" />
      </geometry>
    </collision>
  </link>
  <joint
    name="J4"
    type="revolute">
    <origin
      xyz="0.11785 -0.0003 0.00515"
      rpy="0 0 -3.1416" />
    <parent
      link="link3" />
    <child
      link="link4" />
    <axis
      xyz="0 0 1" />
    <limit
      lower="0"
      upper="3.14"
      effort="0.13"
      velocity="8.72" />
  </joint>
  <link
    name="link6">
    <inertial>
      <origin
        xyz="0.00039698 -0.0062489 0.002"
        rpy="0 0 0" />
      <mass
        value="0.002" />
      <inertia
        ixx="3.3647E-07"
        ixy="1.6687E-08"
        ixz="-1.7255E-17"
        iyy="7.4869E-08"
        iyz="3.4134E-16"
        izz="4.0497E-07" />
    </inertial>
    <visual>
      <origin
        xyz="0 0 0"
        rpy="0 0 0" />
      <geometry>
        <mesh
          filename="file:///home/ahmed/Robotics-Project-main/src/my_robot_arm_pkg/meshes/link6.STL" />
      </geometry>
      <material
        name="">
        <color
          rgba="0.4 0.4 0.4 1.0" />
      </material>
    </visual>
    <collision>
      <origin
        xyz="0 0 0"
        rpy="0 0 0" />
      <geometry>
        <mesh
          filename="file:///home/ahmed/Robotics-Project-main/src/my_robot_arm_pkg/meshes/link6.STL" />
      </geometry>
    </collision>
  </link>
  <joint
    name="J6"
    type="revolute">
    <origin
      xyz="-0.01585 0.0581 -0.0194"
      rpy="3.1416 1.5708 0" />
    <parent
      link="link4" />
    <child
      link="link6" />
    <axis
      xyz="0 0 -1" />
    <limit
      upper="0"
      lower="-1.501"
      effort="0.13"
      velocity="8.72" />
  </joint>
  <link
    name="leftTip">
    <inertial>
      <origin
        xyz="-0.0066699 -0.026438 -0.003425"
        rpy="0 0 0" />
      <mass
        value="0.0028" />
      <inertia
        ixx="1.3145E-06"
        ixy="-2.1507E-07"
        ixz="9.0908E-12"
        iyy="1.0069E-07"
        iyz="6.1836E-13"
        izz="1.3812E-06" />
    </inertial>
    <visual>
      <origin
        xyz="0 0 0"
        rpy="0 0 0" />
      <geometry>
        <mesh
          filename="file:///home/ahmed/Robotics-Project-main/src/my_robot_arm_pkg/meshes/leftTip.STL" />
      </geometry>
      <material
        name="">
        <color
          rgba="0.52 0.58 0.65 1.0" />
      </material>
    </visual>
    <collision>
      <origin
        xyz="0 0 0"
        rpy="0 0 0" />
      <geometry>
        <mesh
          filename="file:///home/ahmed/Robotics-Project-main/src/my_robot_arm_pkg/meshes/leftTip.STL" />
      </geometry>
    </collision>
  </link>
  <joint name="leftTip_joint" type="revolute">
    <origin xyz="0.0019496 -0.030688 0" rpy="0 0 0" />
    <parent link="link6" />
    <child link="leftTip" />
    <axis xyz="0 0 1" />
    <limit upper="0" lower="-1.501" effort="10" velocity="1.0" />
  </joint>
  <link
    name="link5">
    <inertial>
      <origin
        xyz="-0.00039698 -0.0062489 0.002"
        rpy="0 0 0" />
      <mass
        value="0.002" />
      <inertia
        ixx="3.3647E-07"
        ixy="-1.6687E-08"
        ixz="1.7255E-17"
        iyy="7.4869E-08"
        iyz="3.4134E-16"
        izz="4.0497E-07" />
    </inertial>
    <visual>
      <origin
        xyz="0 0 0"
        rpy="0 0 0" />
      <geometry>
        <mesh
          filename="file:///home/ahmed/Robotics-Project-main/src/my_robot_arm_pkg/meshes/link5.STL" />
      </geometry>
      <material
        name="">
        <color
          rgba="0.4 0.4 0.4 1.0" />
      </material>
    </visual>
    <collision>
      <origin
        xyz="0 0 0"
        rpy="0 0 0" />
      <geometry>
        <mesh
          filename="file:///home/ahmed/Robotics-Project-main/src/my_robot_arm_pkg/meshes/link5.STL" />
      </geometry>
    </collision>
  </link>
  <joint
    name="J5"
    type="revolute">
    <origin
      xyz="-0.01585 0.0581 0.0084"
      rpy="3.1416 1.5708 0" />
    <parent
      link="link4" />
    <child
      link="link5" />
    <axis
      xyz="0 0 -1" />
    <limit
      upper="1.501"
      lower="0"
      effort="0.13"
      velocity="8.72" />
  </joint>
  <link
    name="rightTip">
    <inertial>
      <origin
        xyz="0.0066699 -0.026438 -0.003425"
        rpy="0 0 0" />
      <mass
        value="0.0028" />
      <inertia
        ixx="1.3145E-06"
        ixy="2.1507E-07"
        ixz="9.0903E-12"
        iyy="1.0069E-07"
        iyz="-6.1572E-13"
        izz="1.3812E-06" />
    </inertial>
    <visual>
      <origin
        xyz="0 0 0"
        rpy="0 0 0" />
      <geometry>
        <mesh
          filename="file:///home/ahmed/Robotics-Project-main/src/my_robot_arm_pkg/meshes/rightTip.STL" />
      </geometry>
      <material
        name="">
        <color
          rgba="0.52 0.58 0.65 1.0" />
      </material>
    </visual>
    <collision>
      <origin
        xyz="0 0 0"
        rpy="0 0 0" />
      <geometry>
        <mesh
          filename="file:///home/ahmed/Robotics-Project-main/src/my_robot_arm_pkg/meshes/rightTip.STL" />
      </geometry>
    </collision>
  </link>
  <joint name="rightTip_joint" type="revolute">
    <origin xyz="-0.0019496 -0.030688 0" rpy="0 0 0" />
    <parent link="link5" />
    <child link="rightTip" />
    <axis xyz="0 0 1" />
    <limit lower="0" upper="1.5" effort="10" velocity="1.0" />
  </joint>

  <ros2_control name="RobotSystem" type="system">
    <hardware>
      <plugin>gz_ros2_control/GazeboSimSystem</plugin>
    </hardware>

    <joint name="J1">
      <command_interface name="position"/>
      <state_interface name="position"/>
      <state_interface name="velocity"/>
    </joint>
    <joint name="J2">
      <command_interface name="position"/>
      <state_interface name="position"/>
      <state_interface name="velocity"/>
    </joint>
    <joint name="J3">
      <command_interface name="position"/>
      <state_interface name="position"/>
      <state_interface name="velocity"/>
    </joint>
    <joint name="J4">
      <command_interface name="position"/>
      <state_interface name="position"/>
      <state_interface name="velocity"/>
    </joint>
    <joint name="J5">
      <command_interface name="position"/>
      <state_interface name="position"/>
      <state_interface name="velocity"/>
    </joint>
    <joint name="J6">
      <command_interface name="position"/>
      <state_interface name="position"/>
      <state_interface name="velocity"/>
    </joint>
    <joint name="leftTip_joint">
      <command_interface name="position"/>
      <state_interface name="position"/>
      <state_interface name="velocity"/>
    </joint>
    <joint name="rightTip_joint">
      <command_interface name="position"/>
      <state_interface name="position"/>
      <state_interface name="velocity"/>
    </joint>
  </ros2_control>

  <gazebo>
    <plugin filename="gz_ros2_control-system" name="gz_ros2_control::GazeboSimROS2ControlPlugin">
      <parameters>/home/ahmed/Robotics-Project-main/install/my_robot_arm_pkg/share/my_robot_arm_pkg/config/joint_controllers.yaml</parameters>
    </plugin>
  </gazebo>
</robot>